<?xml version="1.0" encoding="utf-8"?>
<!-- This URDF was automatically created by SolidWorks to URDF Exporter! Originally created by Stephen Brawner (brawner@gmail.com) 
     Commit Version: 1.6.0-4-g7f85cfe  Build Version: 1.6.7995.38578
     For more information, please see http://wiki.ros.org/sw_urdf_exporter -->
<robot
  name="wheelchair_gp_description">
  <link
    name="base_link">
    <inertial>
      <origin
        xyz="-0.039757 -0.019357 -0.039165"
        rpy="0 0 0" />
      <mass
        value="13.933" />
      <inertia
        ixx="0.33097"
        ixy="0.00044744"
        ixz="0.022658"
        iyy="0.46476"
        iyz="0.0084497"
        izz="0.49394" />
    </inertial>
    <visual>
      <origin
        xyz="0 0 0"
        rpy="0 0 0" />
      <geometry>
        <mesh
          filename="package://wheelchair_gp_description/meshes/base_link.STL" />
      </geometry>
      <material
        name="">
        <color
          rgba="1 1 1 0.35" />
      </material>
    </visual>
    <collision>
      <origin
        xyz="0 0 0"
        rpy="0 0 0" />
      <geometry>
        <mesh
          filename="package://wheelchair_gp_description/meshes/base_link.STL" />
      </geometry>
    </collision>
  </link>
  <link
    name="right_wheel_link">
    <inertial>
      <origin
        xyz="0.00510162770348606 -0.030000000000002 -0.00883712628242242"
        rpy="0 0 0" />
      <mass
        value="3.63792559240615" />
      <inertia
        ixx="0.0501393580967394"
        ixy="1.12107821276125E-19"
        ixz="-8.37248749195825E-07"
        iyy="0.0986432390550648"
        iyz="1.67001456507497E-16"
        izz="0.0501416739249588" />
    </inertial>
    <visual>
      <origin
        xyz="0 0 0"
        rpy="0 0 0" />
      <geometry>
        <mesh
          filename="package://wheelchair_gp_description/meshes/right_wheel_link.STL" />
      </geometry>
      <material
        name="">
        <color
          rgba="0.298039215686275 0.298039215686275 0.298039215686275 1" />
      </material>
    </visual>
    <collision>
      <origin
        xyz="0 0 0"
        rpy="0 0 0" />
      <geometry>
        <mesh
          filename="package://wheelchair_gp_description/meshes/right_wheel_link.STL" />
      </geometry>
    </collision>
  </link>
  <joint
    name="right_wheel_joint"
    type="continuous">
    <origin
      xyz="-0.0782370331711224 -0.291972990052419 -0.168374239027783"
      rpy="0 0 0" />
    <parent
      link="base_link" />
    <child
      link="right_wheel_link" />
    <axis
      xyz="0 1 0" />
    <dynamics
      damping="0"
      friction="0.2" />
  </joint>
  <link
    name="left_wheel_link">
    <inertial>
      <origin
        xyz="0.00019641498461731 0.0300000000000018 -7.01814500627673E-05"
        rpy="0 0 0" />
      <mass
        value="3.63792559240615" />
      <inertia
        ixx="0.0501416166910778"
        ixy="-4.04263461901347E-18"
        ixz="-9.11182521543636E-07"
        iyy="0.0986432390550647"
        iyz="1.94384416365527E-16"
        izz="0.0501394153306204" />
    </inertial>
    <visual>
      <origin
        xyz="0 0 0"
        rpy="0 0 0" />
      <geometry>
        <mesh
          filename="package://wheelchair_gp_description/meshes/left_wheel_link.STL" />
      </geometry>
      <material
        name="">
        <color
          rgba="0.298039215686275 0.298039215686275 0.298039215686275 1" />
      </material>
    </visual>
    <collision>
      <origin
        xyz="0 0 0"
        rpy="0 0 0" />
      <geometry>
        <mesh
          filename="package://wheelchair_gp_description/meshes/left_wheel_link.STL" />
      </geometry>
    </collision>
  </link>
  <joint
    name="left_wheel_joint"
    type="continuous">
    <origin
      xyz="-0.0732001426526983 0.274956682906951 -0.177013089293031"
      rpy="0 0 0" />
    <parent
      link="base_link" />
    <child
      link="left_wheel_link" />
    <axis
      xyz="0 1 0" />
    <dynamics
      damping="0"
      friction="0.2" />
  </joint>
  <link
    name="c_rr_link">
    <inertial>
      <origin
        xyz="-3.13828650289061E-08 -0.0203309650537574 0.0403769854454989"
        rpy="0 0 0" />
      <mass
        value="0.121211258399187" />
      <inertia
        ixx="0.000183879326955444"
        ixy="2.26483161975211E-11"
        ixz="-3.32770031580253E-12"
        iyy="0.000178527913603531"
        iyz="-2.16822895135042E-05"
        izz="2.37333780216088E-05" />
    </inertial>
    <visual>
      <origin
        xyz="0 0 0"
        rpy="0 0 0" />
      <geometry>
        <mesh
          filename="package://wheelchair_gp_description/meshes/c_rr_link.STL" />
      </geometry>
      <material
        name="">
        <color
          rgba="1 1 1 1" />
      </material>
    </visual>
    <collision>
      <origin
        xyz="0 0 0"
        rpy="0 0 0" />
      <geometry>
        <mesh
          filename="package://wheelchair_gp_description/meshes/c_rr_link.STL" />
      </geometry>
    </collision>
  </link>
  <joint
    name="c_rr_joint"
    type="continuous">
    <origin
      xyz="-0.393409036225651 -0.350252210665998 -0.277013089293034"
      rpy="0 0 0" />
    <parent
      link="base_link" />
    <child
      link="c_rr_link" />
    <axis
      xyz="0 0 1" />
    <dynamics
      damping="0"
      friction="0.01" />
  </joint>
  <link
    name="wheel_rr_link">
    <inertial>
      <origin
        xyz="6.66133814775094E-16 -0.0760000000000002 -9.99200722162641E-16"
        rpy="0 0 0" />
      <mass
        value="1.6546211917139" />
      <inertia
        ixx="0.00469812484295985"
        ixy="3.09869809237376E-10"
        ixz="2.19664192882436E-19"
        iyy="0.00853457249449096"
        iyz="-1.14225228777157E-10"
        izz="0.00469812484295985" />
    </inertial>
    <visual>
      <origin
        xyz="0 0 0"
        rpy="0 0 0" />
      <geometry>
        <mesh
          filename="package://wheelchair_gp_description/meshes/wheel_rr_link.STL" />
      </geometry>
      <material
        name="">
        <color
          rgba="0.298039215686275 0.298039215686275 0.298039215686275 1" />
      </material>
    </visual>
    <collision>
      <origin
        xyz="0 0 0"
        rpy="0 0 0" />
      <geometry>
        <mesh
          filename="package://wheelchair_gp_description/meshes/wheel_rr_link.STL" />
      </geometry>
    </collision>
  </link>
  <joint
    name="wheel_rr_joint"
    type="continuous">
    <origin
      xyz="0 0 0"
      rpy="0 0 0" />
    <parent
      link="c_rr_link" />
    <child
      link="wheel_rr_link" />
    <axis
      xyz="0 -1 0" />
    <dynamics
      damping="0"
      friction="0.01" />
  </joint>
  <link
    name="c_rl_link">
    <inertial>
      <origin
        xyz="3.13828648623726E-08 0.0203309650537573 0.0403769854454998"
        rpy="0 0 0" />
      <mass
        value="0.121211258399187" />
      <inertia
        ixx="0.000183879326955444"
        ixy="2.26483161958936E-11"
        ixz="3.32770035341549E-12"
        iyy="0.000178527913603531"
        iyz="2.16822895135046E-05"
        izz="2.37333780216089E-05" />
    </inertial>
    <visual>
      <origin
        xyz="0 0 0"
        rpy="0 0 0" />
      <geometry>
        <mesh
          filename="package://wheelchair_gp_description/meshes/c_rl_link.STL" />
      </geometry>
      <material
        name="">
        <color
          rgba="1 1 1 1" />
      </material>
    </visual>
    <collision>
      <origin
        xyz="0 0 0"
        rpy="0 0 0" />
      <geometry>
        <mesh
          filename="package://wheelchair_gp_description/meshes/c_rl_link.STL" />
      </geometry>
    </collision>
  </link>
  <joint
    name="c_rl_joint"
    type="continuous">
    <origin
      xyz="-0.372337227642546 0.31893664115027 -0.277013089293036"
      rpy="0 0 0" />
    <parent
      link="base_link" />
    <child
      link="c_rl_link" />
    <axis
      xyz="0 0 1" />
    <dynamics
      damping="0"
      friction="0.01" />
  </joint>
  <link
    name="wheel_rl_link">
    <inertial>
      <origin
        xyz="-2.22044604925031E-16 0.076000000000002 5.77315972805081E-15"
        rpy="0 0 0" />
      <mass
        value="1.65462119171389" />
      <inertia
        ixx="0.0046981248429598"
        ixy="-1.37193710697435E-10"
        ixz="-1.72593884581092E-19"
        iyy="0.00853457249449089"
        iyz="-3.00407370002668E-10"
        izz="0.0046981248429598" />
    </inertial>
    <visual>
      <origin
        xyz="0 0 0"
        rpy="0 0 0" />
      <geometry>
        <mesh
          filename="package://wheelchair_gp_description/meshes/wheel_rl_link.STL" />
      </geometry>
      <material
        name="">
        <color
          rgba="0.298039215686275 0.298039215686275 0.298039215686275 1" />
      </material>
    </visual>
    <collision>
      <origin
        xyz="0 0 0"
        rpy="0 0 0" />
      <geometry>
        <mesh
          filename="package://wheelchair_gp_description/meshes/wheel_rl_link.STL" />
      </geometry>
    </collision>
  </link>
  <joint
    name="wheel_rl_joint"
    type="continuous">
    <origin
      xyz="0 0 0"
      rpy="0 0 0" />
    <parent
      link="c_rl_link" />
    <child
      link="wheel_rl_link" />
    <axis
      xyz="0 1 0" />
    <dynamics
      damping="0"
      friction="0.01" />
  </joint>
  <link
    name="c_fl_link">
    <inertial>
      <origin
        xyz="3.13828648068615E-08 0.0043309650537573 0.0403769854455019"
        rpy="0 0 0" />
      <mass
        value="0.121211258399187" />
      <inertia
        ixx="0.000183879326955444"
        ixy="2.26483161953357E-11"
        ixz="3.32770038421124E-12"
        iyy="0.000178527913603531"
        iyz="2.16822895135046E-05"
        izz="2.37333780216089E-05" />
    </inertial>
    <visual>
      <origin
        xyz="0 0 0"
        rpy="0 0 0" />
      <geometry>
        <mesh
          filename="package://wheelchair_gp_description/meshes/c_fl_link.STL" />
      </geometry>
      <material
        name="">
        <color
          rgba="1 1 1 1" />
      </material>
    </visual>
    <collision>
      <origin
        xyz="0 0 0"
        rpy="0 0 0" />
      <geometry>
        <mesh
          filename="package://wheelchair_gp_description/meshes/c_fl_link.STL" />
      </geometry>
    </collision>
  </link>
  <joint
    name="c_fl_joint"
    type="continuous">
    <origin
      xyz="0.27689495464306 0.30405178020271 -0.277013089293036"
      rpy="0 0 0" />
    <parent
      link="base_link" />
    <child
      link="c_fl_link" />
    <axis
      xyz="0 0 1" />
    <dynamics
      damping="0"
      friction="0.01" />
  </joint>
  <link
    name="wheel_fl_link">
    <inertial>
      <origin
        xyz="0.00446139900539488 0.0330891569793361 -0.00894963233404278"
        rpy="0 0 0" />
      <mass
        value="1.65462119171389" />
      <inertia
        ixx="0.00469812484295982"
        ixy="-3.2855366928529E-10"
        ixz="1.63590639821193E-18"
        iyy="0.0085345724944909"
        iyz="-3.34543045516606E-11"
        izz="0.00469812484295982" />
    </inertial>
    <visual>
      <origin
        xyz="0 0 0"
        rpy="0 0 0" />
      <geometry>
        <mesh
          filename="package://wheelchair_gp_description/meshes/wheel_fl_link.STL" />
      </geometry>
      <material
        name="">
        <color
          rgba="0.298039215686275 0.298039215686275 0.298039215686275 1" />
      </material>
    </visual>
    <collision>
      <origin
        xyz="0 0 0"
        rpy="0 0 0" />
      <geometry>
        <mesh
          filename="package://wheelchair_gp_description/meshes/wheel_fl_link.STL" />
      </geometry>
    </collision>
  </link>
  <joint
    name="wheel_fl_joint"
    type="continuous">
    <origin
      xyz="-0.00446139900539422 0.0269108430206658 0.00894963233404933"
      rpy="0 0 0" />
    <parent
      link="c_fl_link" />
    <child
      link="wheel_fl_link" />
    <axis
      xyz="0 -1 0" />
    <dynamics
      damping="0"
      friction="0.01" />
  </joint>
  <link
    name="c_fr_link">
    <inertial>
      <origin
        xyz="-3.13828649178838E-08 -0.00433096505375735 0.0403769854454989"
        rpy="0 0 0" />
      <mass
        value="0.121211258399187" />
      <inertia
        ixx="0.000183879326955444"
        ixy="2.26483162485928E-11"
        ixz="-3.32769997596411E-12"
        iyy="0.000178527913603531"
        iyz="-2.16822895135042E-05"
        izz="2.37333780216088E-05" />
    </inertial>
    <visual>
      <origin
        xyz="0 0 0"
        rpy="0 0 0" />
      <geometry>
        <mesh
          filename="package://wheelchair_gp_description/meshes/c_fr_link.STL" />
      </geometry>
      <material
        name="">
        <color
          rgba="1 1 1 1" />
      </material>
    </visual>
    <collision>
      <origin
        xyz="0 0 0"
        rpy="0 0 0" />
      <geometry>
        <mesh
          filename="package://wheelchair_gp_description/meshes/c_fr_link.STL" />
      </geometry>
    </collision>
  </link>
  <joint
    name="c_fr_joint"
    type="continuous">
    <origin
      xyz="0.283824627602434 -0.321068087348177 -0.277013089293038"
      rpy="0 0 0" />
    <parent
      link="base_link" />
    <child
      link="c_fr_link" />
    <axis
      xyz="0 0 1" />
    <dynamics
      damping="0"
      friction="0.01" />
  </joint>
  <link
    name="wheel_fr_link">
    <inertial>
      <origin
        xyz="5.55111512312578E-17 -0.05 2.22044604925031E-16"
        rpy="0 0 0" />
      <mass
        value="1.65462119171388" />
      <inertia
        ixx="0.0046981248429598"
        ixy="-6.92222670801156E-11"
        ixz="3.43454942193008E-19"
        iyy="0.00853457249449086"
        iyz="-3.22916359624308E-10"
        izz="0.0046981248429598" />
    </inertial>
    <visual>
      <origin
        xyz="0 0 0"
        rpy="0 0 0" />
      <geometry>
        <mesh
          filename="package://wheelchair_gp_description/meshes/wheel_fr_link.STL" />
      </geometry>
      <material
        name="">
        <color
          rgba="0.298039215686275 0.298039215686275 0.298039215686275 1" />
      </material>
    </visual>
    <collision>
      <origin
        xyz="0 0 0"
        rpy="0 0 0" />
      <geometry>
        <mesh
          filename="package://wheelchair_gp_description/meshes/wheel_fr_link.STL" />
      </geometry>
    </collision>
  </link>
  <joint
    name="wheel_fr_joint"
    type="continuous">
    <origin
      xyz="0 -0.01 0"
      rpy="0 0 0" />
    <parent
      link="c_fr_link" />
    <child
      link="wheel_fr_link" />
    <axis
      xyz="0 1 0" />
    <dynamics
      damping="0"
      friction="0.01" />
  </joint>
  <link
    name="chair_link">
    <inertial>
      <origin
        xyz="-0.10157 -0.021818 0.4723"
        rpy="0 0 0" />
      <mass
        value="15.71" />
      <inertia
        ixx="0.008371"
        ixy="0.019686"
        ixz="0.0024599"
        iyy="0.0905"
        iyz="0.0070802"
        izz="0.0060145" />
    </inertial>
    <visual>
      <origin
        xyz="0 0 0"
        rpy="0 0 0" />
      <geometry>
        <mesh
          filename="package://wheelchair_gp_description/meshes/chair_link.STL" />
      </geometry>
      <material
        name="">
        <color
          rgba="1 1 1 0.35" />
      </material>
    </visual>
    <collision>
      <origin
        xyz="0 0 0"
        rpy="0 0 0" />
      <geometry>
        <mesh
          filename="package://wheelchair_gp_description/meshes/chair_link.STL" />
      </geometry>
    </collision>
  </link>
  <joint
    name="chair_joint"
    type="fixed">
    <origin
      xyz="0 0 0"
      rpy="0 0 0" />
    <parent
      link="base_link" />
    <child
      link="chair_link" />
    <axis
      xyz="0 0 0" />
    <dynamics
      damping="0"
      friction="0" />
  </joint>
  <link
    name="laser_link">
    <inertial>
      <origin
        xyz="0.000495105100789484 0.0164439657014417 0.00393830931158456"
        rpy="0 0 0" />
      <mass
        value="0.171592914783825" />
      <inertia
        ixx="8.81695728106642E-05"
        ixy="1.0242870227811E-06"
        ixz="-2.45165014566817E-07"
        iyy="5.5532059341782E-05"
        iyz="-4.34620831675872E-06"
        izz="0.000129552220460151" />
    </inertial>
    <visual>
      <origin
        xyz="0 0 0"
        rpy="0 0 0" />
      <geometry>
        <mesh
          filename="package://wheelchair_gp_description/meshes/laser_link.STL" />
      </geometry>
      <material
        name="">
        <color
          rgba="1 1 1 0.3" />
      </material>
    </visual>
    <collision>
      <origin
        xyz="0 0 0"
        rpy="0 0 0" />
      <geometry>
        <mesh
          filename="package://wheelchair_gp_description/meshes/laser_link.STL" />
      </geometry>
    </collision>
  </link>
  <joint
    name="laser_joint"
    type="fixed">
    <origin
      xyz="-0.289700142652701 -0.0219729900524268 1.41197884354779"
      rpy="0 0 0" />
    <parent
      link="chair_link" />
    <child
      link="laser_link" />
    <axis
      xyz="0 0 0" />
    <dynamics
      damping="0"
      friction="0" />
  </joint>
  <link
    name="imu_link">
    <inertial>
      <origin
        xyz="0.018949 0.005 -0.010521"
        rpy="0 0 0" />
      <mass
        value="0.0081342" />
      <inertia
        ixx="3.6792E-07"
        ixy="-1.2671E-21"
        ixz="1.2472E-21"
        iyy="1.2738E-06"
        iyz="-2.1176E-22"
        izz="1.0414E-06" />
    </inertial>
    <visual>
      <origin
        xyz="0 0 0"
        rpy="0 0 0" />
      <geometry>
        <mesh
          filename="package://wheelchair_gp_description/meshes/imu_link.STL" />
      </geometry>
      <material
        name="">
        <color
          rgba="1 1 1 1" />
      </material>
    </visual>
    <collision>
      <origin
        xyz="0 0 0"
        rpy="0 0 0" />
      <geometry>
        <mesh
          filename="package://wheelchair_gp_description/meshes/imu_link.STL" />
      </geometry>
    </collision>
  </link>
  <joint
    name="imu_joint"
    type="fixed">
    <origin
      xyz="0.156900923854985 0.0739145260442063 0.136986910706968"
      rpy="1.5707963267949 0 0" />
    <parent
      link="base_link" />
    <child
      link="imu_link" />
    <axis
      xyz="0 0 0" />
    <dynamics
      damping="0"
      friction="0" />
  </joint>
  <link
    name="sonar1_link">
    <inertial>
      <origin
        xyz="0.03 0.01 0.0125"
        rpy="0 0 0" />
      <mass
        value="0.0260730091830128" />
      <inertia
        ixx="2.33342553567574E-06"
        ixy="2.39750637008089E-22"
        ixz="4.13279061765283E-21"
        iyy="8.76262920888084E-06"
        iyz="-5.24053573970192E-23"
        izz="8.38011628799275E-06" />
    </inertial>
    <visual>
      <origin
        xyz="0 0 0"
        rpy="0 0 0" />
      <geometry>
        <mesh
          filename="package://wheelchair_gp_description/meshes/sonar1_link.STL" />
      </geometry>
      <material
        name="">
        <color
          rgba="0.792156862745098 0.819607843137255 0.933333333333333 1" />
      </material>
    </visual>
    <collision>
      <origin
        xyz="0 0 0"
        rpy="0 0 0" />
      <geometry>
        <mesh
          filename="package://wheelchair_gp_description/meshes/sonar1_link.STL" />
      </geometry>
    </collision>
  </link>
  <joint
    name="sonar1_frame"
    type="fixed">
    <origin
      xyz="0.209699857347303 -0.271972990052421 0.0212022900160468"
      rpy="1.5707963267949 0 1.5707963267949" />
    <parent
      link="base_link" />
    <child
      link="sonar1_link" />
    <axis
      xyz="0 0 0" />
  </joint>
  <link
    name="sonar2_link">
    <inertial>
      <origin
        xyz="-0.0259807621134805 0.00999999999999989 0.0125"
        rpy="0 0 0" />
      <mass
        value="0.0260730091830128" />
      <inertia
        ixx="2.33342553567575E-06"
        ixy="-2.34670732739222E-20"
        ixz="4.60574165069522E-21"
        iyy="8.76262920888086E-06"
        iyz="-1.04096839012415E-22"
        izz="8.38011628799278E-06" />
    </inertial>
    <visual>
      <origin
        xyz="0 0 0"
        rpy="0 0 0" />
      <geometry>
        <mesh
          filename="package://wheelchair_gp_description/meshes/sonar2_link.STL" />
      </geometry>
      <material
        name="">
        <color
          rgba="0.792156862745098 0.819607843137255 0.933333333333333 1" />
      </material>
    </visual>
    <collision>
      <origin
        xyz="0 0 0"
        rpy="0 0 0" />
      <geometry>
        <mesh
          filename="package://wheelchair_gp_description/meshes/sonar2_link.STL" />
      </geometry>
    </collision>
  </link>
  <joint
    name="sonar2_frame"
    type="fixed">
    <origin
      xyz="0.203696157664793 -0.214605255589858 -0.0087977099839529"
      rpy="1.57079632679489 0 1.83259571459405" />
    <parent
      link="base_link" />
    <child
      link="sonar2_link" />
    <axis
      xyz="0 0 0" />
  </joint>
</robot>